(0.001) 
            SELECT name, type FROM sqlite_master
            WHERE type in ('table', 'view') AND NOT name='sqlite_sequence'
            ORDER BY name; args=None
(0.001) SELECT "django_migrations"."app", "django_migrations"."name" FROM "django_migrations"; args=()
(0.002) SELECT "eems_beacon_log"."id", "eems_beacon_log"."reply_token", "eems_beacon_log"."line_id", "eems_beacon_log"."timestamp", "eems_beacon_log"."hwid", "eems_beacon_log"."enter_or_leave" FROM "eems_beacon_log"; args=()
"GET /log/ HTTP/1.1" 200 17519
"GET /static/images/favicon.png HTTP/1.1" 200 1503
(0.001) 
            SELECT name, type FROM sqlite_master
            WHERE type in ('table', 'view') AND NOT name='sqlite_sequence'
            ORDER BY name; args=None
(0.001) SELECT "django_migrations"."app", "django_migrations"."name" FROM "django_migrations"; args=()
(0.001) SELECT "eems_beacon_log"."id", "eems_beacon_log"."reply_token", "eems_beacon_log"."line_id", "eems_beacon_log"."timestamp", "eems_beacon_log"."hwid", "eems_beacon_log"."enter_or_leave" FROM "eems_beacon_log"; args=()
"GET /log/ HTTP/1.1" 200 17519
"GET /static/images/favicon.png HTTP/1.1" 200 1503
Exception while resolving variable 'name' in template 'unknown'.
Traceback (most recent call last):
  File "C:\python\lib\site-packages\django\core\handlers\exception.py", line 35, in inner
    response = get_response(request)
  File "C:\python\lib\site-packages\django\core\handlers\base.py", line 113, in _get_response
    resolver_match = resolver.resolve(request.path_info)
  File "C:\python\lib\site-packages\django\urls\resolvers.py", line 523, in resolve
    raise Resolver404({'tried': tried, 'path': new_path})
django.urls.exceptions.Resolver404: {'tried': [[<URLResolver <URLPattern list> (admin:admin) 'admin/'>], [<URLPattern ''>], [<URLPattern 'log/'>], [<URLPattern 'webhook' [name='webhook']>]], 'path': 'log/buttons.html'}

During handling of the above exception, another exception occurred:

Traceback (most recent call last):
  File "C:\python\lib\site-packages\django\template\base.py", line 835, in _resolve_lookup
    current = current[bit]
TypeError: 'URLResolver' object is not subscriptable

During handling of the above exception, another exception occurred:

Traceback (most recent call last):
  File "C:\python\lib\site-packages\django\template\base.py", line 843, in _resolve_lookup
    current = getattr(current, bit)
AttributeError: 'URLResolver' object has no attribute 'name'

During handling of the above exception, another exception occurred:

Traceback (most recent call last):
  File "C:\python\lib\site-packages\django\template\base.py", line 849, in _resolve_lookup
    current = current[int(bit)]
ValueError: invalid literal for int() with base 10: 'name'

During handling of the above exception, another exception occurred:

Traceback (most recent call last):
  File "C:\python\lib\site-packages\django\template\base.py", line 856, in _resolve_lookup
    (bit, current))  # missing attribute
django.template.base.VariableDoesNotExist: Failed lookup for key [name] in <URLResolver <URLPattern list> (admin:admin) 'admin/'>
Not Found: /log/buttons.html
"GET /log/buttons.html HTTP/1.1" 404 2314
(0.000) 
            SELECT name, type FROM sqlite_master
            WHERE type in ('table', 'view') AND NOT name='sqlite_sequence'
            ORDER BY name; args=None
(0.000) SELECT "django_migrations"."app", "django_migrations"."name" FROM "django_migrations"; args=()
(0.001) SELECT "eems_beacon_log"."id", "eems_beacon_log"."reply_token", "eems_beacon_log"."line_id", "eems_beacon_log"."timestamp", "eems_beacon_log"."hwid", "eems_beacon_log"."enter_or_leave" FROM "eems_beacon_log"; args=()
"GET /log/ HTTP/1.1" 200 17519
"GET / HTTP/1.1" 200 51680
Exception while resolving variable 'name' in template 'unknown'.
Traceback (most recent call last):
  File "C:\python\lib\site-packages\django\core\handlers\exception.py", line 35, in inner
    response = get_response(request)
  File "C:\python\lib\site-packages\django\core\handlers\base.py", line 113, in _get_response
    resolver_match = resolver.resolve(request.path_info)
  File "C:\python\lib\site-packages\django\urls\resolvers.py", line 523, in resolve
    raise Resolver404({'tried': tried, 'path': new_path})
django.urls.exceptions.Resolver404: {'tried': [[<URLResolver <URLPattern list> (admin:admin) 'admin/'>], [<URLPattern ''>], [<URLPattern 'log/'>], [<URLPattern 'webhook' [name='webhook']>]], 'path': 'buttons.html'}

During handling of the above exception, another exception occurred:

Traceback (most recent call last):
  File "C:\python\lib\site-packages\django\template\base.py", line 835, in _resolve_lookup
    current = current[bit]
TypeError: 'URLResolver' object is not subscriptable

During handling of the above exception, another exception occurred:

Traceback (most recent call last):
  File "C:\python\lib\site-packages\django\template\base.py", line 843, in _resolve_lookup
    current = getattr(current, bit)
AttributeError: 'URLResolver' object has no attribute 'name'

During handling of the above exception, another exception occurred:

Traceback (most recent call last):
  File "C:\python\lib\site-packages\django\template\base.py", line 849, in _resolve_lookup
    current = current[int(bit)]
ValueError: invalid literal for int() with base 10: 'name'

During handling of the above exception, another exception occurred:

Traceback (most recent call last):
  File "C:\python\lib\site-packages\django\template\base.py", line 856, in _resolve_lookup
    (bit, current))  # missing attribute
django.template.base.VariableDoesNotExist: Failed lookup for key [name] in <URLResolver <URLPattern list> (admin:admin) 'admin/'>
Not Found: /buttons.html
"GET /buttons.html HTTP/1.1" 404 2302
(0.002) 
            SELECT name, type FROM sqlite_master
            WHERE type in ('table', 'view') AND NOT name='sqlite_sequence'
            ORDER BY name; args=None
(0.001) SELECT "django_migrations"."app", "django_migrations"."name" FROM "django_migrations"; args=()
"GET / HTTP/1.1" 200 51680
"GET /static/images/favicon.png HTTP/1.1" 200 1503
(0.002) SELECT "eems_beacon_log"."id", "eems_beacon_log"."reply_token", "eems_beacon_log"."line_id", "eems_beacon_log"."timestamp", "eems_beacon_log"."hwid", "eems_beacon_log"."enter_or_leave" FROM "eems_beacon_log"; args=()
"GET /log/ HTTP/1.1" 200 17519
(0.001) 
            SELECT name, type FROM sqlite_master
            WHERE type in ('table', 'view') AND NOT name='sqlite_sequence'
            ORDER BY name; args=None
(0.000) SELECT "django_migrations"."app", "django_migrations"."name" FROM "django_migrations"; args=()
(0.001) SELECT "eems_beacon_log"."id", "eems_beacon_log"."reply_token", "eems_beacon_log"."line_id", "eems_beacon_log"."timestamp", "eems_beacon_log"."hwid", "eems_beacon_log"."enter_or_leave" FROM "eems_beacon_log"; args=()
"GET /log/ HTTP/1.1" 200 17519
"GET /static/images/favicon.png HTTP/1.1" 200 1503
(0.001) SELECT "eems_beacon_log"."id", "eems_beacon_log"."reply_token", "eems_beacon_log"."line_id", "eems_beacon_log"."timestamp", "eems_beacon_log"."hwid", "eems_beacon_log"."enter_or_leave" FROM "eems_beacon_log"; args=()
"GET /log/ HTTP/1.1" 200 17519
Exception while resolving variable 'name' in template 'unknown'.
Traceback (most recent call last):
  File "C:\python\lib\site-packages\django\core\handlers\exception.py", line 35, in inner
    response = get_response(request)
  File "C:\python\lib\site-packages\django\core\handlers\base.py", line 113, in _get_response
    resolver_match = resolver.resolve(request.path_info)
  File "C:\python\lib\site-packages\django\urls\resolvers.py", line 523, in resolve
    raise Resolver404({'tried': tried, 'path': new_path})
django.urls.exceptions.Resolver404: {'tried': [[<URLResolver <URLPattern list> (admin:admin) 'admin/'>], [<URLPattern ''>], [<URLPattern 'log/'>], [<URLPattern 'webhook' [name='webhook']>]], 'path': 'log/buttons.html'}

During handling of the above exception, another exception occurred:

Traceback (most recent call last):
  File "C:\python\lib\site-packages\django\template\base.py", line 835, in _resolve_lookup
    current = current[bit]
TypeError: 'URLResolver' object is not subscriptable

During handling of the above exception, another exception occurred:

Traceback (most recent call last):
  File "C:\python\lib\site-packages\django\template\base.py", line 843, in _resolve_lookup
    current = getattr(current, bit)
AttributeError: 'URLResolver' object has no attribute 'name'

During handling of the above exception, another exception occurred:

Traceback (most recent call last):
  File "C:\python\lib\site-packages\django\template\base.py", line 849, in _resolve_lookup
    current = current[int(bit)]
ValueError: invalid literal for int() with base 10: 'name'

During handling of the above exception, another exception occurred:

Traceback (most recent call last):
  File "C:\python\lib\site-packages\django\template\base.py", line 856, in _resolve_lookup
    (bit, current))  # missing attribute
django.template.base.VariableDoesNotExist: Failed lookup for key [name] in <URLResolver <URLPattern list> (admin:admin) 'admin/'>
Not Found: /log/buttons.html
"GET /log/buttons.html HTTP/1.1" 404 2314
(0.001) 
            SELECT name, type FROM sqlite_master
            WHERE type in ('table', 'view') AND NOT name='sqlite_sequence'
            ORDER BY name; args=None
(0.000) SELECT "django_migrations"."app", "django_migrations"."name" FROM "django_migrations"; args=()
(0.001) SELECT "eems_beacon_log"."id", "eems_beacon_log"."reply_token", "eems_beacon_log"."line_id", "eems_beacon_log"."timestamp", "eems_beacon_log"."hwid", "eems_beacon_log"."enter_or_leave" FROM "eems_beacon_log"; args=()
"GET /log/ HTTP/1.1" 200 17519
"GET /static/images/favicon.png HTTP/1.1" 200 1503
Exception while resolving variable 'name' in template 'unknown'.
Traceback (most recent call last):
  File "C:\python\lib\site-packages\django\core\handlers\exception.py", line 35, in inner
    response = get_response(request)
  File "C:\python\lib\site-packages\django\core\handlers\base.py", line 113, in _get_response
    resolver_match = resolver.resolve(request.path_info)
  File "C:\python\lib\site-packages\django\urls\resolvers.py", line 523, in resolve
    raise Resolver404({'tried': tried, 'path': new_path})
django.urls.exceptions.Resolver404: {'tried': [[<URLResolver <URLPattern list> (admin:admin) 'admin/'>], [<URLPattern ''>], [<URLPattern 'log/'>], [<URLPattern 'webhook' [name='webhook']>]], 'path': 'log/charts.html'}

During handling of the above exception, another exception occurred:

Traceback (most recent call last):
  File "C:\python\lib\site-packages\django\template\base.py", line 835, in _resolve_lookup
    current = current[bit]
TypeError: 'URLResolver' object is not subscriptable

During handling of the above exception, another exception occurred:

Traceback (most recent call last):
  File "C:\python\lib\site-packages\django\template\base.py", line 843, in _resolve_lookup
    current = getattr(current, bit)
AttributeError: 'URLResolver' object has no attribute 'name'

During handling of the above exception, another exception occurred:

Traceback (most recent call last):
  File "C:\python\lib\site-packages\django\template\base.py", line 849, in _resolve_lookup
    current = current[int(bit)]
ValueError: invalid literal for int() with base 10: 'name'

During handling of the above exception, another exception occurred:

Traceback (most recent call last):
  File "C:\python\lib\site-packages\django\template\base.py", line 856, in _resolve_lookup
    (bit, current))  # missing attribute
django.template.base.VariableDoesNotExist: Failed lookup for key [name] in <URLResolver <URLPattern list> (admin:admin) 'admin/'>
Not Found: /log/charts.html
"GET /log/charts.html HTTP/1.1" 404 2311
(0.002) SELECT "eems_beacon_log"."id", "eems_beacon_log"."reply_token", "eems_beacon_log"."line_id", "eems_beacon_log"."timestamp", "eems_beacon_log"."hwid", "eems_beacon_log"."enter_or_leave" FROM "eems_beacon_log"; args=()
"GET /log/ HTTP/1.1" 200 17519
(0.001) 
            SELECT name, type FROM sqlite_master
            WHERE type in ('table', 'view') AND NOT name='sqlite_sequence'
            ORDER BY name; args=None
(0.000) SELECT "django_migrations"."app", "django_migrations"."name" FROM "django_migrations"; args=()
(0.001) SELECT "eems_beacon_log"."id", "eems_beacon_log"."reply_token", "eems_beacon_log"."line_id", "eems_beacon_log"."timestamp", "eems_beacon_log"."hwid", "eems_beacon_log"."enter_or_leave" FROM "eems_beacon_log"; args=()
"GET /log/ HTTP/1.1" 200 17519
"GET /static/images/favicon.png HTTP/1.1" 200 1503
"GET / HTTP/1.1" 200 51680
Exception while resolving variable 'name' in template 'unknown'.
Traceback (most recent call last):
  File "C:\python\lib\site-packages\django\core\handlers\exception.py", line 35, in inner
    response = get_response(request)
  File "C:\python\lib\site-packages\django\core\handlers\base.py", line 113, in _get_response
    resolver_match = resolver.resolve(request.path_info)
  File "C:\python\lib\site-packages\django\urls\resolvers.py", line 523, in resolve
    raise Resolver404({'tried': tried, 'path': new_path})
django.urls.exceptions.Resolver404: {'tried': [[<URLResolver <URLPattern list> (admin:admin) 'admin/'>], [<URLPattern ''>], [<URLPattern 'log/'>], [<URLPattern 'webhook' [name='webhook']>]], 'path': 'buttons.html'}

During handling of the above exception, another exception occurred:

Traceback (most recent call last):
  File "C:\python\lib\site-packages\django\template\base.py", line 835, in _resolve_lookup
    current = current[bit]
TypeError: 'URLResolver' object is not subscriptable

During handling of the above exception, another exception occurred:

Traceback (most recent call last):
  File "C:\python\lib\site-packages\django\template\base.py", line 843, in _resolve_lookup
    current = getattr(current, bit)
AttributeError: 'URLResolver' object has no attribute 'name'

During handling of the above exception, another exception occurred:

Traceback (most recent call last):
  File "C:\python\lib\site-packages\django\template\base.py", line 849, in _resolve_lookup
    current = current[int(bit)]
ValueError: invalid literal for int() with base 10: 'name'

During handling of the above exception, another exception occurred:

Traceback (most recent call last):
  File "C:\python\lib\site-packages\django\template\base.py", line 856, in _resolve_lookup
    (bit, current))  # missing attribute
django.template.base.VariableDoesNotExist: Failed lookup for key [name] in <URLResolver <URLPattern list> (admin:admin) 'admin/'>
Not Found: /buttons.html
"GET /buttons.html HTTP/1.1" 404 2302
